Workbook

Sheet Instructions
A1: MARHANA & CO CONSULTING LTD — SALES PIPELINE TRACKER
A2: The Company's own pipeline. This is not T18, which reports opportunities to a retainer client.
A5: HOW TO USE
A6: 1. | B6: Add one row per opportunity on the Pipeline sheet. Blue cells are for you to type in; black cells calculate themselves — do not overwrite them.
A7: 2. | B7: Stage, Sector, Service, Source and Outcome are dropdowns. Their contents are on the Lists sheet — edit them there, not in the Pipeline sheet.
A8: 3. | B8: Probability fills in automatically from the Stage. Override it in column J only where you have a specific reason, and note the reason in Notes.
A9: 4. | B9: Fill in 'Next action' and 'Next action date' on every live row. A row with no next action is not a pipeline entry, it is a memory.
A10: 5. | B10: Work the Pipeline sheet weekly. Sort by 'Days since contact' and deal with the top of the list first.
A11: 6. | B11: The Dashboard updates automatically. Read it at the start of each week and at the monthly review.
A12: 7. | B12: Log every call, email and meeting on the Activity sheet. Outreach volume is the one number in this workbook you fully control.
A14: COLOUR KEY
A15: Blue text | B15: You type here
A16: Black text | B16: Calculated — leave alone
A17: Yellow fill | B17: Assumption you should set before using the workbook
A19: THE STAGES
A20: 1. Identified | B20: You know the organisation exists and looks like a fit. No contact yet.
A21: 2. Contacted | B21: You have made contact. No response yet.
A22: 3. Engaged | B22: They have replied and a conversation is happening.
A23: 4. Qualified | B23: You have established they have a live need, a budget and someone who can decide.
A24: 5. Proposal sent | B24: A Proposal and Fee Quotation (T14) has been issued.
A25: 6. Negotiating | B25: They are discussing scope, price or timing.
A26: 7. Won | B26: Terms of Engagement accepted. Move the fee to the Won column.
A27: 8. Lost | B27: Record the reason. The reason is worth more than the entry.
A28: 9. Dormant | B28: No decision, no fault. Set a review date and stop chasing weekly.
A30: A NOTE ON WEIGHTED VALUE
B31: Weighted value is the mid-point of the fee band multiplied by the probability. It is a planning figure, not a forecast. With a small number of opportunities it will be wrong in any given month; it is useful only as a trend across several.

Sheet Lists
A1: PICK LISTS — edit here, the dropdowns follow
A3: Stage | B3: Default probability | C3: Sector | D3: Service | E3: Source | F3: Outcome reason | H3: Fee band mid-points (from the Schedule of Fees)
A4: 1. Identified | B4: 0.05 | C4: Construction and trades | D4: Bid Fit Score | E4: Referral — existing client | F4: Won | H4: Service | I4: Low | J4: High | K4: Mid
A5: 2. Contacted | B5: 0.1 | C5: Health and social care | D5: Bid Readiness Assessment | E5: Referral — partner | F5: Lost — price | H5: Bid Fit Score | I5: 150 | J5: 350 | K5: =(I5+J5)/2 -> 250
A6: 3. Engaged | B6: 0.2 | C6: NHS-adjacent supply | D6: Post-tender debrief analysis | E6: Personal network | F6: Lost — chose a competitor | H6: Bid Readiness Assessment | I6: 250 | J6: 500 | K6: =(I6+J6)/2 -> 375
A7: 4. Qualified | B7: 0.35 | C7: Facilities management | D7: Bid review and rewrite | E7: Cold outreach — email | F7: Lost — did it in house | H7: Post-tender debrief analysis | I7: 200 | J7: 450 | K7: =(I7+J7)/2 -> 325
A8: 5. Proposal sent | B8: 0.5 | C8: Housing and maintenance | D8: Tender and PQQ writing | E8: Cold outreach — LinkedIn | F8: Lost — decided not to bid | H8: Bid review and rewrite | I8: 250 | J8: 600 | K8: =(I8+J8)/2 -> 425
A9: 6. Negotiating | B9: 0.7 | C9: Education supply | D9: Social value statements | E9: Cold outreach — telephone | F9: Lost — no track record / too new | H9: Tender and PQQ writing | I9: 500 | J9: 2000 | K9: =(I9+J9)/2 -> 1250
A10: 7. Won | B10: 1 | C10: Professional services | D10: Financial and costed business case | E10: Inbound — website | F10: Lost — timing | H10: Social value statements | I10: 300 | J10: 900 | K10: =(I10+J10)/2 -> 600
A11: 8. Lost | B11: 0 | C11: Other | D11: Accreditation support | E11: Event | F11: No decision — went quiet | H11: Financial and costed business case | I11: 300 | J11: 800 | K11: =(I11+J11)/2 -> 550
A12: 9. Dormant | B12: 0.05 | D12: Evidence Bank development | E12: Contract Finder / Find a Tender research | F12: Disqualified on conflict | H12: Accreditation support | I12: 300 | J12: 700 | K12: =(I12+J12)/2 -> 500
D13: Framework applications | E13: Other | F13: Withdrew | H13: Evidence Bank development | I13: 800 | J13: 2000 | K13: =(I13+J13)/2 -> 1400
D14: Consortium bid coordination | H14: Framework applications | I14: 800 | J14: 2500 | K14: =(I14+J14)/2 -> 1650
D15: Contract mobilisation | H15: Consortium bid coordination | I15: 900 | J15: 2500 | K15: =(I15+J15)/2 -> 1700
D16: Social value delivery reporting | H16: Contract mobilisation | I16: 400 | J16: 1200 | K16: =(I16+J16)/2 -> 800
D17: Retainer | H17: Social value delivery reporting | I17: 300 | J17: 600 | K17: =(I17+J17)/2 -> 450
H18: Retainer | I18: 0 | J18: 0 | K18: =(I18+J18)/2 -> 0
H19: Retainer: set the monthly fee manually on the Pipeline sheet — tiers are not fixed.

Sheet Pipeline
A1: PIPELINE
A2: Blue = you type. Black = calculated. Row 4 is a worked example — delete it before use.
A3: Ref | B3: Date added | C3: Organisation | D3: Contact name | E3: Contact details | F3: Sector | G3: Source | H3: Service | I3: Stage | J3: Prob. | K3: Fee low | L3: Fee high | M3: Weighted | N3: Quote sent | O3: Decision due | P3: Last contact | Q3: Days since | R3: Next action | S3: Next action date | T3: Outcome | U3: Notes
A4: OPP-001 | B4: =DATE(2026,8,19) -> 46253 | C4: [Example] Northgate Roofing Ltd | D4: A. Example | E4: example@… / 020 0000 0000 | F4: Construction and trades | G4: Referral — partner | H4: Bid Readiness Assessment | I4: 4. Qualified | J4: =IFERROR(INDEX(Lists!$B$4:$B$12,MATCH(I4,Lists!$A$4:$A$12,0)),"") -> 0.35 | K4: =IFERROR(INDEX(Lists!$I$5:$I$18,MATCH(H4,Lists!$H$5:$H$18,0)),"") -> 250 | L4: =IFERROR(INDEX(Lists!$J$5:$J$18,MATCH(H4,Lists!$H$5:$H$18,0)),"") -> 500 | M4: =IFERROR(((K4+L4)/2)*J4,"") -> 131.25 | O4: =DATE(2026,9,25) -> 46290 | P4: =DATE(2026,9,2) -> 46267 | Q4: =IF(P4="","",TODAY()-P4) -> 9 | R4: Send T14 quotation | S4: =DATE(2026,9,15) -> 46280 | U4: Chasing a council framework; no evidence bank at all
J5: =IFERROR(INDEX(Lists!$B$4:$B$12,MATCH(I5,Lists!$A$4:$A$12,0)),"") | K5: =IFERROR(INDEX(Lists!$I$5:$I$18,MATCH(H5,Lists!$H$5:$H$18,0)),"") | L5: =IFERROR(INDEX(Lists!$J$5:$J$18,MATCH(H5,Lists!$H$5:$H$18,0)),"") | M5: =IFERROR(((K5+L5)/2)*J5,"") | Q5: =IF(P5="","",TODAY()-P5)
J6: =IFERROR(INDEX(Lists!$B$4:$B$12,MATCH(I6,Lists!$A$4:$A$12,0)),"") | K6: =IFERROR(INDEX(Lists!$I$5:$I$18,MATCH(H6,Lists!$H$5:$H$18,0)),"") | L6: =IFERROR(INDEX(Lists!$J$5:$J$18,MATCH(H6,Lists!$H$5:$H$18,0)),"") | M6: =IFERROR(((K6+L6)/2)*J6,"") | Q6: =IF(P6="","",TODAY()-P6)
J7: =IFERROR(INDEX(Lists!$B$4:$B$12,MATCH(I7,Lists!$A$4:$A$12,0)),"") | K7: =IFERROR(INDEX(Lists!$I$5:$I$18,MATCH(H7,Lists!$H$5:$H$18,0)),"") | L7: =IFERROR(INDEX(Lists!$J$5:$J$18,MATCH(H7,Lists!$H$5:$H$18,0)),"") | M7: =IFERROR(((K7+L7)/2)*J7,"") | Q7: =IF(P7="","",TODAY()-P7)
J8: =IFERROR(INDEX(Lists!$B$4:$B$12,MATCH(I8,Lists!$A$4:$A$12,0)),"") | K8: =IFERROR(INDEX(Lists!$I$5:$I$18,MATCH(H8,Lists!$H$5:$H$18,0)),"") | L8: =IFERROR(INDEX(Lists!$J$5:$J$18,MATCH(H8,Lists!$H$5:$H$18,0)),"") | M8: =IFERROR(((K8+L8)/2)*J8,"") | Q8: =IF(P8="","",TODAY()-P8)
J9: =IFERROR(INDEX(Lists!$B$4:$B$12,MATCH(I9,Lists!$A$4:$A$12,0)),"") | K9: =IFERROR(INDEX(Lists!$I$5:$I$18,MATCH(H9,Lists!$H$5:$H$18,0)),"") | L9: =IFERROR(INDEX(Lists!$J$5:$J$18,MATCH(H9,Lists!$H$5:$H$18,0)),"") | M9: =IFERROR(((K9+L9)/2)*J9,"") | Q9: =IF(P9="","",TODAY()-P9)
J10: =IFERROR(INDEX(Lists!$B$4:$B$12,MATCH(I10,Lists!$A$4:$A$12,0)),"") | K10: =IFERROR(INDEX(Lists!$I$5:$I$18,MATCH(H10,Lists!$H$5:$H$18,0)),"") | L10: =IFERROR(INDEX(Lists!$J$5:$J$18,MATCH(H10,Lists!$H$5:$H$18,0)),"") | M10: =IFERROR(((K10+L10)/2)*J10,"") | Q10: =IF(P10="","",TODAY()-P10)
J11: =IFERROR(INDEX(Lists!$B$4:$B$12,MATCH(I11,Lists!$A$4:$A$12,0)),"") | K11: =IFERROR(INDEX(Lists!$I$5:$I$18,MATCH(H11,Lists!$H$5:$H$18,0)),"") | L11: =IFERROR(INDEX(Lists!$J$5:$J$18,MATCH(H11,Lists!$H$5:$H$18,0)),"") | M11: =IFERROR(((K11+L11)/2)*J11,"") | Q11: =IF(P11="","",TODAY()-P11)
J12: =IFERROR(INDEX(Lists!$B$4:$B$12,MATCH(I12,Lists!$A$4:$A$12,0)),"") | K12: =IFERROR(INDEX(Lists!$I$5:$I$18,MATCH(H12,Lists!$H$5:$H$18,0)),"") | L12: =IFERROR(INDEX(Lists!$J$5:$J$18,MATCH(H12,Lists!$H$5:$H$18,0)),"") | M12: =IFERROR(((K12+L12)/2)*J12,"") | Q12: =IF(P12="","",TODAY()-P12)
J13: =IFERROR(INDEX(Lists!$B$4:$B$12,MATCH(I13,Lists!$A$4:$A$12,0)),"") | K13: =IFERROR(INDEX(Lists!$I$5:$I$18,MATCH(H13,Lists!$H$5:$H$18,0)),"") | L13: =IFERROR(INDEX(Lists!$J$5:$J$18,MATCH(H13,Lists!$H$5:$H$18,0)),"") | M13: =IFERROR(((K13+L13)/2)*J13,"") | Q13: =IF(P13="","",TODAY()-P13)
J14: =IFERROR(INDEX(Lists!$B$4:$B$12,MATCH(I14,Lists!$A$4:$A$12,0)),"") | K14: =IFERROR(INDEX(Lists!$I$5:$I$18,MATCH(H14,Lists!$H$5:$H$18,0)),"") | L14: =IFERROR(INDEX(Lists!$J$5:$J$18,MATCH(H14,Lists!$H$5:$H$18,0)),"") | M14: =IFERROR(((K14+L14)/2)*J14,"") | Q14: =IF(P14="","",TODAY()-P14)
J15: =IFERROR(INDEX(Lists!$B$4:$B$12,MATCH(I15,Lists!$A$4:$A$12,0)),"") | K15: =IFERROR(INDEX(Lists!$I$5:$I$18,MATCH(H15,Lists!$H$5:$H$18,0)),"") | L15: =IFERROR(INDEX(Lists!$J$5:$J$18,MATCH(H15,Lists!$H$5:$H$18,0)),"") | M15: =IFERROR(((K15+L15)/2)*J15,"") | Q15: =IF(P15="","",TODAY()-P15)
J16: =IFERROR(INDEX(Lists!$B$4:$B$12,MATCH(I16,Lists!$A$4:$A$12,0)),"") | K16: =IFERROR(INDEX(Lists!$I$5:$I$18,MATCH(H16,Lists!$H$5:$H$18,0)),"") | L16: =IFERROR(INDEX(Lists!$J$5:$J$18,MATCH(H16,Lists!$H$5:$H$18,0)),"") | M16: =IFERROR(((K16+L16)/2)*J16,"") | Q16: =IF(P16="","",TODAY()-P16)
... J63: =IFERROR(INDEX(Lists!$B$4:$B$12,MATCH(I63,Lists!$A$4:$A$12,0)),"") | K63: =IFERROR(INDEX(Lists!$I$5:$I$18,MATCH(H63,Lists!$H$5:$H$18,0)),"") | L63: =IFERROR(INDEX(Lists!$J$5:$J$18,MATCH(H63,Lists!$H$5:$H$18,0)),"") | M63: =IFERROR(((K63+L63)/2)*J63,"") | Q63: =IF(P63="","",TODAY()-P63)
H65: TOTALS | K65: =SUM(K4:K63) -> 250 | L65: =SUM(L4:L63) -> 500 | M65: =SUM(M4:M63) -> 131.25
H66: Weighted total is a planning figure, not a forecast.

Sheet Dashboard
A1: DASHBOARD
A2: All figures calculate from the Pipeline and Activity sheets.
A4: BY STAGE
A5: Stage | B5: Count | C5: Fee low | D5: Fee high | E5: Weighted
A6: 1. Identified | B6: =COUNTIFS(Pipeline!$I$4:$I$63,$A6) -> 0 | C6: =SUMIFS(Pipeline!$K$4:$K$63,Pipeline!$I$4:$I$63,$A6) -> 0 | D6: =SUMIFS(Pipeline!$L$4:$L$63,Pipeline!$I$4:$I$63,$A6) -> 0 | E6: =SUMIFS(Pipeline!$M$4:$M$63,Pipeline!$I$4:$I$63,$A6) -> 0
A7: 2. Contacted | B7: =COUNTIFS(Pipeline!$I$4:$I$63,$A7) -> 0 | C7: =SUMIFS(Pipeline!$K$4:$K$63,Pipeline!$I$4:$I$63,$A7) -> 0 | D7: =SUMIFS(Pipeline!$L$4:$L$63,Pipeline!$I$4:$I$63,$A7) -> 0 | E7: =SUMIFS(Pipeline!$M$4:$M$63,Pipeline!$I$4:$I$63,$A7) -> 0
A8: 3. Engaged | B8: =COUNTIFS(Pipeline!$I$4:$I$63,$A8) -> 0 | C8: =SUMIFS(Pipeline!$K$4:$K$63,Pipeline!$I$4:$I$63,$A8) -> 0 | D8: =SUMIFS(Pipeline!$L$4:$L$63,Pipeline!$I$4:$I$63,$A8) -> 0 | E8: =SUMIFS(Pipeline!$M$4:$M$63,Pipeline!$I$4:$I$63,$A8) -> 0
A9: 4. Qualified | B9: =COUNTIFS(Pipeline!$I$4:$I$63,$A9) -> 1 | C9: =SUMIFS(Pipeline!$K$4:$K$63,Pipeline!$I$4:$I$63,$A9) -> 250 | D9: =SUMIFS(Pipeline!$L$4:$L$63,Pipeline!$I$4:$I$63,$A9) -> 500 | E9: =SUMIFS(Pipeline!$M$4:$M$63,Pipeline!$I$4:$I$63,$A9) -> 131.25
A10: 5. Proposal sent | B10: =COUNTIFS(Pipeline!$I$4:$I$63,$A10) -> 0 | C10: =SUMIFS(Pipeline!$K$4:$K$63,Pipeline!$I$4:$I$63,$A10) -> 0 | D10: =SUMIFS(Pipeline!$L$4:$L$63,Pipeline!$I$4:$I$63,$A10) -> 0 | E10: =SUMIFS(Pipeline!$M$4:$M$63,Pipeline!$I$4:$I$63,$A10) -> 0
A11: 6. Negotiating | B11: =COUNTIFS(Pipeline!$I$4:$I$63,$A11) -> 0 | C11: =SUMIFS(Pipeline!$K$4:$K$63,Pipeline!$I$4:$I$63,$A11) -> 0 | D11: =SUMIFS(Pipeline!$L$4:$L$63,Pipeline!$I$4:$I$63,$A11) -> 0 | E11: =SUMIFS(Pipeline!$M$4:$M$63,Pipeline!$I$4:$I$63,$A11) -> 0
A12: 7. Won | B12: =COUNTIFS(Pipeline!$I$4:$I$63,$A12) -> 0 | C12: =SUMIFS(Pipeline!$K$4:$K$63,Pipeline!$I$4:$I$63,$A12) -> 0 | D12: =SUMIFS(Pipeline!$L$4:$L$63,Pipeline!$I$4:$I$63,$A12) -> 0 | E12: =SUMIFS(Pipeline!$M$4:$M$63,Pipeline!$I$4:$I$63,$A12) -> 0
A13: 8. Lost | B13: =COUNTIFS(Pipeline!$I$4:$I$63,$A13) -> 0 | C13: =SUMIFS(Pipeline!$K$4:$K$63,Pipeline!$I$4:$I$63,$A13) -> 0 | D13: =SUMIFS(Pipeline!$L$4:$L$63,Pipeline!$I$4:$I$63,$A13) -> 0 | E13: =SUMIFS(Pipeline!$M$4:$M$63,Pipeline!$I$4:$I$63,$A13) -> 0
A14: 9. Dormant | B14: =COUNTIFS(Pipeline!$I$4:$I$63,$A14) -> 0 | C14: =SUMIFS(Pipeline!$K$4:$K$63,Pipeline!$I$4:$I$63,$A14) -> 0 | D14: =SUMIFS(Pipeline!$L$4:$L$63,Pipeline!$I$4:$I$63,$A14) -> 0 | E14: =SUMIFS(Pipeline!$M$4:$M$63,Pipeline!$I$4:$I$63,$A14) -> 0
A15: TOTAL | B15: =SUM(B6:B14) -> 1 | C15: =SUM(C6:C14) -> 250 | D15: =SUM(D6:D14) -> 500 | E15: =SUM(E6:E14) -> 131.25
A17: HEADLINE NUMBERS
A18: Measure | B18: Value | C18: What it tells you
A19: Live opportunities (stages 1–6) | B19: =SUM(B6:B11) -> 1 | C19: Everything still in play
A20: Weighted value of live pipeline | B20: =SUM(E6:E11) -> 131.25 | C20: Planning figure only — read the trend, not the number
A21: Won this period | B21: =B12 -> 0 | C21: Count of engagements accepted
A22: Value won (mid-point) | B22: =(C12+D12)/2 -> 0 | C22: Mid-point of the fee bands for won work
A23: Lost | B23: =B13 -> 0 | C23: Count
A24: Win rate on decided opportunities | B24: =IFERROR(B12/(B12+B13),"—") -> — | C24: Won divided by won plus lost. Ignore it below about 10 decisions
A25: Proposals out awaiting decision | B25: =B10+B11 -> 0 | C25: Quotations issued and not yet answered
A26: Opportunities with no contact in 21 days | B26: =COUNTIFS(Pipeline!$Q$4:$Q$63,">21") -> 0 | C26: Your follow-up backlog
A27: Overdue next actions | B27: =COUNTIFS(Pipeline!$S$4:$S$63,"<"&TODAY(),Pipeline!$S$4:$S$63,"<>") -> 0 | C27: Things you said you would do and have not
A28: Outreach logged, last 30 days | B28: =COUNTIFS(Activity!$A$4:$A$203,">="&TODAY()-30) -> 1 | C28: The one number you fully control
A29: Outreach logged, last 7 days | B29: =COUNTIFS(Activity!$A$4:$A$203,">="&TODAY()-7) -> 0 | C29: Weekly activity
A32: BY SECTOR | E32: BY SOURCE — where work actually comes from
A33: Sector | B33: Live count | C33: Weighted value | E33: Source | F33: Count | G33: Won
A34: Construction and trades | B34: =COUNTIFS(Pipeline!$F$4:$F$63,$A34) -> 1 | C34: =SUMIFS(Pipeline!$M$4:$M$63,Pipeline!$F$4:$F$63,$A34) -> 131.25 | E34: Referral — existing client | F34: =COUNTIFS(Pipeline!$G$4:$G$63,$E34) -> 0 | G34: =COUNTIFS(Pipeline!$G$4:$G$63,$E34,Pipeline!$I$4:$I$63,"7. Won") -> 0
A35: Health and social care | B35: =COUNTIFS(Pipeline!$F$4:$F$63,$A35) -> 0 | C35: =SUMIFS(Pipeline!$M$4:$M$63,Pipeline!$F$4:$F$63,$A35) -> 0 | E35: Referral — partner | F35: =COUNTIFS(Pipeline!$G$4:$G$63,$E35) -> 1 | G35: =COUNTIFS(Pipeline!$G$4:$G$63,$E35,Pipeline!$I$4:$I$63,"7. Won") -> 0
A36: NHS-adjacent supply | B36: =COUNTIFS(Pipeline!$F$4:$F$63,$A36) -> 0 | C36: =SUMIFS(Pipeline!$M$4:$M$63,Pipeline!$F$4:$F$63,$A36) -> 0 | E36: Personal network | F36: =COUNTIFS(Pipeline!$G$4:$G$63,$E36) -> 0 | G36: =COUNTIFS(Pipeline!$G$4:$G$63,$E36,Pipeline!$I$4:$I$63,"7. Won") -> 0
A37: Facilities management | B37: =COUNTIFS(Pipeline!$F$4:$F$63,$A37) -> 0 | C37: =SUMIFS(Pipeline!$M$4:$M$63,Pipeline!$F$4:$F$63,$A37) -> 0 | E37: Cold outreach — email | F37: =COUNTIFS(Pipeline!$G$4:$G$63,$E37) -> 0 | G37: =COUNTIFS(Pipeline!$G$4:$G$63,$E37,Pipeline!$I$4:$I$63,"7. Won") -> 0
A38: Housing and maintenance | B38: =COUNTIFS(Pipeline!$F$4:$F$63,$A38) -> 0 | C38: =SUMIFS(Pipeline!$M$4:$M$63,Pipeline!$F$4:$F$63,$A38) -> 0 | E38: Cold outreach — LinkedIn | F38: =COUNTIFS(Pipeline!$G$4:$G$63,$E38) -> 0 | G38: =COUNTIFS(Pipeline!$G$4:$G$63,$E38,Pipeline!$I$4:$I$63,"7. Won") -> 0
A39: Education supply | B39: =COUNTIFS(Pipeline!$F$4:$F$63,$A39) -> 0 | C39: =SUMIFS(Pipeline!$M$4:$M$63,Pipeline!$F$4:$F$63,$A39) -> 0 | E39: Cold outreach — telephone | F39: =COUNTIFS(Pipeline!$G$4:$G$63,$E39) -> 0 | G39: =COUNTIFS(Pipeline!$G$4:$G$63,$E39,Pipeline!$I$4:$I$63,"7. Won") -> 0
A40: Professional services | B40: =COUNTIFS(Pipeline!$F$4:$F$63,$A40) -> 0 | C40: =SUMIFS(Pipeline!$M$4:$M$63,Pipeline!$F$4:$F$63,$A40) -> 0 | E40: Inbound — website | F40: =COUNTIFS(Pipeline!$G$4:$G$63,$E40) -> 0 | G40: =COUNTIFS(Pipeline!$G$4:$G$63,$E40,Pipeline!$I$4:$I$63,"7. Won") -> 0
A41: Other | B41: =COUNTIFS(Pipeline!$F$4:$F$63,$A41) -> 0 | C41: =SUMIFS(Pipeline!$M$4:$M$63,Pipeline!$F$4:$F$63,$A41) -> 0 | E41: Event | F41: =COUNTIFS(Pipeline!$G$4:$G$63,$E41) -> 0 | G41: =COUNTIFS(Pipeline!$G$4:$G$63,$E41,Pipeline!$I$4:$I$63,"7. Won") -> 0
E42: Contract Finder / Find a Tender research | F42: =COUNTIFS(Pipeline!$G$4:$G$63,$E42) -> 0 | G42: =COUNTIFS(Pipeline!$G$4:$G$63,$E42,Pipeline!$I$4:$I$63,"7. Won") -> 0
E43: Other | F43: =COUNTIFS(Pipeline!$G$4:$G$63,$E43) -> 0 | G43: =COUNTIFS(Pipeline!$G$4:$G$63,$E43,Pipeline!$I$4:$I$63,"7. Won") -> 0
A46: WHY WE LOSE
...

Sheet Activity
A1: OUTREACH AND CONTACT LOG
A2: Every call, email, message and meeting. Row 4 is an example — delete it.
A3: Date | B3: Organisation | C3: Person | D3: Channel | E3: Purpose | F3: What happened | G3: Linked opportunity ref | H3: Follow-up date | I3: Done
A4: =DATE(2026,9,2) -> 46267 | B4: [Example] Northgate Roofing Ltd | C4: A. Example | D4: Telephone | E4: Qualify need | F4: Confirmed they are chasing a council framework and have no evidence bank. Quotation to follow. | G4: OPP-001 | H4: =DATE(2026,9,15) -> 46280 | I4: Yes
